Traceback (most recent call last):
  File "C:\Users\User\anaconda3\envs\myenv\lib\site-packages\jupyter_cache\executors\utils.py", line 56, in single_nb_execution
    record_timing=False,
  File "C:\Users\User\anaconda3\envs\myenv\lib\site-packages\nbclient\client.py", line 1117, in execute
    return NotebookClient(nb=nb, resources=resources, km=km, **kwargs).execute()
  File "C:\Users\User\anaconda3\envs\myenv\lib\site-packages\nbclient\util.py", line 78, in wrapped
    return just_run(coro(*args, **kwargs))
  File "C:\Users\User\anaconda3\envs\myenv\lib\site-packages\nbclient\util.py", line 57, in just_run
    return loop.run_until_complete(coro)
  File "C:\Users\User\anaconda3\envs\myenv\lib\asyncio\base_events.py", line 587, in run_until_complete
    return future.result()
  File "C:\Users\User\anaconda3\envs\myenv\lib\site-packages\nbclient\client.py", line 559, in async_execute
    cell, index, execution_count=self.code_cells_executed + 1
  File "C:\Users\User\anaconda3\envs\myenv\lib\site-packages\nbclient\client.py", line 862, in async_execute_cell
    self._check_raise_for_error(cell, exec_reply)
  File "C:\Users\User\anaconda3\envs\myenv\lib\site-packages\nbclient\client.py", line 765, in _check_raise_for_error
    raise CellExecutionError.from_cell_and_msg(cell, exec_reply_content)
nbclient.exceptions.CellExecutionError: An error occurred while executing the following cell:
------------------
import numpy as np
import pandas as pd
from scipy.stats import norm
import seaborn as sns

import matplotlib.pyplot as plt

from numpy import arange

import sklearn
from sklearn.cluster import KMeans
from mpl_toolkits.mplot3d import Axes3D

import sklearn.metrics as sm
from sklearn.decomposition import PCA
from sklearn import datasets
from sklearn.metrics import confusion_matrix, classification_report
------------------

[1;31m---------------------------------------------------------------------------[0m
[1;31mModuleNotFoundError[0m                       Traceback (most recent call last)
[1;32m~\AppData\Local\Temp/ipykernel_7428/2784781905.py[0m in [0;36m<module>[1;34m[0m
[1;32m----> 1[1;33m [1;32mimport[0m [0mnumpy[0m [1;32mas[0m [0mnp[0m[1;33m[0m[1;33m[0m[0m
[0m[0;32m      2[0m [1;32mimport[0m [0mpandas[0m [1;32mas[0m [0mpd[0m[1;33m[0m[1;33m[0m[0m
[0;32m      3[0m [1;32mfrom[0m [0mscipy[0m[1;33m.[0m[0mstats[0m [1;32mimport[0m [0mnorm[0m[1;33m[0m[1;33m[0m[0m
[0;32m      4[0m [1;32mimport[0m [0mseaborn[0m [1;32mas[0m [0msns[0m[1;33m[0m[1;33m[0m[0m
[0;32m      5[0m [1;33m[0m[0m

[1;31mModuleNotFoundError[0m: No module named 'numpy'
ModuleNotFoundError: No module named 'numpy'

